Workbook

Sheet Read me
A1: How far do ASX shares actually fall? — the working
A2: Every figure printed in the article, and the data it was computed from. Figures on sheets 2–5 are live Excel formulas over sheet 6 — click any number to see its working.
A4: What this workbook is
B5: The article states 51 measured figures. This file contains all of them, the company-level data underneath them, and the formula that turns one into the other. Nothing is pasted as a value: every published number on sheets 2–5 recalculates from sheet 6 when you open it.
A7: The measurement
A8: What we measured | B8: For each company: every price fall deeper than 5%, and the AVERAGE depth of those falls. One number per company — its "typical fall".
A9: Measured from | B9: The company's highest point in the PREVIOUS 252 trading days (about one year) — not from an all-time record. This is deliberately a question about ordinary setbacks.
A10: Window | B10: 1 January 2000 to 26 August 2026, daily closing prices.
A11: Why 2000 | B11: Our price history has a different hard floor per country: the US begins in 1962, Canada in 1995, Australia in 1988. 2000 is the first year that is complete for all three, so it is the only window in which the three can honestly be compared.
A12: Universe | B12: Current members of the ASX 200, the S&P 500 and the S&P/TSX 60. Companies we cover but that are not in one of those three indices are included on sheet 6 for context and are EXCLUDED from every published figure.
A13: Settings | B13: The product's own Medium preset: -5% pullback, +5% rebound, 252-day lookback.
A14: Computed by | B14: analytics/major_cycle.py — the same code that runs on the site. Not a separate calculation written for the article.
A16: How the index figure is built
B17: Each index figure is the MEDIAN of its member companies' typical falls — the middle company, not the average. A median is used because a handful of very volatile companies would drag an average and misdescribe the typical member.
A19: How to check a number
A20: 1 | B20: Open sheet 2, 3, 4 or 5 and click any percentage.
A21: 2 | B21: The formula bar shows the exact rows on sheet 6 that produced it, e.g. =MEDIAN('6 · Company data'!O5:O205).
A22: 3 | B22: Select those rows on sheet 6. Excel's status bar shows the count and average; the companies are listed by name.
A23: 4 | B23: Sheet 8 lists five figures you can confirm on a public website in a few minutes, with links.
A25: Reading the numbers
A26: Units | B26: All percentages are stored as plain numbers (-21.7 means a 21.7% fall) so they can be averaged directly. They are only FORMATTED with a % sign.
A27: Negative = a fall | B27: Typical fall, worst fall and current fall are all negative. Deeper is more negative.
A28: Market cap | B28: Used only to rank companies WITHIN their own index (sheet 3). Each index is priced in one currency — ASX in AUD, S&P 500 in USD, TSX in CAD — so a rank inside an index is sound, and a cap comparison ACROSS indices is not. The article never makes one.
A30: What this file cannot tell you
B31: It cannot verify the cycle mathematics itself — that runs in Python before this file exists. What it verifies is everything built on top: which companies were included, what each one measured, and whether the published medians, tables and ratios follow from those company numbers.
B32: It is also a snapshot. Prices move, so re-running the study on a later date will move the figures. The article is dated 26 August 2026 for exactly this reason.

Sheet 1 · Article figures
A1: Every figure in the article
A2: 51 measured figures, each with the sheet that computes it. Green = reproduced exactly from the data when this file was built.
A4: Figure as printed in the article | B4: Value | C4: Computed on | D4: Note
A5: ASX 200 — typical fall | B5: -21.7 | C5: 2 · Headline | D5: Median of 201 members
A6: S&P 500 — typical fall | B6: -18.9 | C6: 2 · Headline | D6: Median of 500 members
A7: S&P/TSX 60 — typical fall | B7: -15.8 | C7: 2 · Headline | D7: Median of 60 members
A8: ASX 200, largest 60 only | B8: -18.4 | C8: 3 · Size-matched | D8: The reversal the article turns on
A9: S&P 500, largest 60 only | B9: -19 | C9: 3 · Size-matched
A10: S&P/TSX 60, largest 60 only | B10: -15.8 | C10: 3 · Size-matched | D10: Unchanged — the index IS its 60
A11: Real Estate — ASX 200 | B11: -16 | C11: 4 · By sector
A12: Real Estate — S&P 500 | B12: -17.4 | C12: 4 · By sector
A13: Real Estate — S&P/TSX 60 | B13: — | C13: 4 · By sector | D13: Printed as '—': only 1 companies, too few for a median
A14: Financial Services — ASX 200 | B14: -18.5 | C14: 4 · By sector
A15: Financial Services — S&P 500 | B15: -18.4 | C15: 4 · By sector
A16: Financial Services — S&P/TSX 60 | B16: -14.6 | C16: 4 · By sector
A17: Healthcare — ASX 200 | B17: -19.1 | C17: 4 · By sector
A18: Healthcare — S&P 500 | B18: -18.5 | C18: 4 · By sector
A19: Healthcare — S&P/TSX 60 | B19: — | C19: 4 · By sector | D19: Printed as '—': only 0 companies, too few for a median
A20: Consumer Cyclical — ASX 200 | B20: -19.7 | C20: 4 · By sector
A21: Consumer Cyclical — S&P 500 | B21: -21.7 | C21: 4 · By sector
A22: Consumer Cyclical — S&P/TSX 60 | B22: -16.3 | C22: 4 · By sector
A23: Consumer Defensive — ASX 200 | B23: -20.4 | C23: 4 · By sector
A24: Consumer Defensive — S&P 500 | B24: -15 | C24: 4 · By sector
A25: Consumer Defensive — S&P/TSX 60 | B25: -13.4 | C25: 4 · By sector
A26: Industrials — ASX 200 | B26: -21.7 | C26: 4 · By sector
A27: Industrials — S&P 500 | B27: -17.8 | C27: 4 · By sector
A28: Industrials — S&P/TSX 60 | B28: -14.2 | C28: 4 · By sector
A29: Technology — ASX 200 | B29: -24.6 | C29: 4 · By sector
A30: Technology — S&P 500 | B30: -22.1 | C30: 4 · By sector
A31: Technology — S&P/TSX 60 | B31: -23 | C31: 4 · By sector
... A37: Basic Materials — S&P/TSX 60 | B37: -23.8 | C37: 4 · By sector
A38: Commonwealth Bank of Australia — typical fall | B38: -14.3 | C38: 5 · Banks vs miners | D38: CBA.AX
A39: Westpac Banking Corporation — typical fall | B39: -14.8 | C39: 5 · Banks vs miners | D39: WBC.AX
A40: ANZ Group Holdings Limited — typical fall | B40: -15.5 | C40: 5 · Banks vs miners | D40: ANZ.AX
A41: National Australia Bank Limited — typical fall | B41: -15.6 | C41: 5 · Banks vs miners | D41: NAB.AX
A42: Bendigo and Adelaide Bank Limited — typical fall | B42: -16.9 | C42: 5 · Banks vs miners | D42: BEN.AX
A43: Bank of Queensland Limited — typical fall | B43: -18.5 | C43: 5 · Banks vs miners | D43: BOQ.AX
A44: Macquarie Group Limited — typical fall | B44: -19 | C44: 5 · Banks vs miners | D44: MQG.AX
A45: BHP Group Limited — typical fall | B45: -16.9 | C45: 5 · Banks vs miners | D45: BHP.AX
A46: Rio Tinto Group — typical fall | B46: -17 | C46: 5 · Banks vs miners | D46: RIO.AX
...

Sheet 2 · Headline
A1: The headline number
A2: The middle company of each index. Read plainly this says Australian shares fall harder — sheet 3 is why that is the wrong conclusion.
A4: Index | B4: Typical fall | C4: Companies | D4: The formula, in words
A5: ASX 200 | B5: =MEDIAN('6 · Company data'!$O$5:$O$205) | C5: =COUNT('6 · Company data'!$O$5:$O$205) | D5: The middle value of the 201 typical falls in that block of sheet 6
A6: S&P 500 | B6: =MEDIAN('6 · Company data'!$O$206:$O$705) | C6: =COUNT('6 · Company data'!$O$206:$O$705) | D6: The middle value of the 500 typical falls in that block of sheet 6
A7: S&P/TSX 60 | B7: =MEDIAN('6 · Company data'!$O$706:$O$765) | C7: =COUNT('6 · Company data'!$O$706:$O$765) | D7: The middle value of the 60 typical falls in that block of sheet 6
A9: Why a median, not an average?
A10: A handful of very volatile companies would drag an average and misdescribe the typical member. The median is the middle company: half fall less than this, half fall more.

Sheet 3 · Size-matched
A1: Comparing like with like — the largest 60 in each index
A2: The TSX 60 holds sixty companies; the ASX 200 holds two hundred, reaching much further into mid-sized businesses, and smaller companies fall harder everywhere. So: the largest 60 of each.
A4: Index | B4: All members | C4: Largest 60 only | D4: Difference | E4: The formula, in words
A5: ASX 200 | B5: =MEDIAN('6 · Company data'!$O$5:$O$205) | C5: =MEDIAN('6 · Company data'!$S$5:$S$205) | D5: =C5-B5 | E5: Column S on sheet 6 holds the typical fall ONLY for companies ranked 1–60 by market cap in their own index; blanks are ignored by MEDIAN.
A6: S&P 500 | B6: =MEDIAN('6 · Company data'!$O$206:$O$705) | C6: =MEDIAN('6 · Company data'!$S$206:$S$705) | D6: =C6-B6
A7: S&P/TSX 60 | B7: =MEDIAN('6 · Company data'!$O$706:$O$765) | C7: =MEDIAN('6 · Company data'!$S$706:$S$765) | D7: =C7-B7 | E7: Unchanged — the index is only 60 companies
A9: The gap does not narrow — it reverses.
A10: Australia's sixty biggest listed companies have fallen slightly LESS than America's sixty biggest. The difference in the headline was never about Australia; it was about what the ASX 200 holds.

Sheet 4 · By sector
A1: Typical fall by sector
A2: Sectors are ordered shallowest to deepest by the ASX column. A dash means that index holds fewer than five companies in the sector — too few for a median worth printing.
A4: Sector | B4: ASX 200 | C4: n | D4: S&P 500 | E4: n | F4: S&P/TSX 60 | G4: n | H4: Note
A5: Real Estate | B5: =MEDIAN('6 · Company data'!$O$171:$O$189) | C5: =COUNT('6 · Company data'!$O$171:$O$189) | D5: =MEDIAN('6 · Company data'!$O$563:$O$591) | E5: =COUNT('6 · Company data'!$O$563:$O$591) | F5: — | G5: =COUNT('6 · Company data'!$O$756:$O$756)
A6: Financial Services | B6: =MEDIAN('6 · Company data'!$O$109:$O$136) | C6: =COUNT('6 · Company data'!$O$109:$O$136) | D6: =MEDIAN('6 · Company data'!$O$360:$O$429) | E6: =COUNT('6 · Company data'!$O$360:$O$429) | F6: =MEDIAN('6 · Company data'!$O$737:$O$749) | G6: =COUNT('6 · Company data'!$O$737:$O$749)
A7: Healthcare | B7: =MEDIAN('6 · Company data'!$O$137:$O$149) | C7: =COUNT('6 · Company data'!$O$137:$O$149) | D7: =MEDIAN('6 · Company data'!$O$430:$O$488) | E7: =COUNT('6 · Company data'!$O$430:$O$488) | F7: — | G7: 0
A8: Consumer Cyclical | B8: =MEDIAN('6 · Company data'!$O$68:$O$86) | C8: =COUNT('6 · Company data'!$O$68:$O$86) | D8: =MEDIAN('6 · Company data'!$O$252:$O$305) | E8: =COUNT('6 · Company data'!$O$252:$O$305) | F8: =MEDIAN('6 · Company data'!$O$717:$O$722) | G8: =COUNT('6 · Company data'!$O$717:$O$722)
A9: Consumer Defensive | B9: =MEDIAN('6 · Company data'!$O$87:$O$95) | C9: =COUNT('6 · Company data'!$O$87:$O$95) | D9: =MEDIAN('6 · Company data'!$O$306:$O$338) | E9: =COUNT('6 · Company data'!$O$306:$O$338) | F9: =MEDIAN('6 · Company data'!$O$723:$O$727) | G9: =COUNT('6 · Company data'!$O$723:$O$727)
A10: Industrials | B10: =MEDIAN('6 · Company data'!$O$150:$O$170) | C10: =COUNT('6 · Company data'!$O$150:$O$170) | D10: =MEDIAN('6 · Company data'!$O$489:$O$562) | E10: =COUNT('6 · Company data'!$O$489:$O$562) | F10: =MEDIAN('6 · Company data'!$O$750:$O$755) | G10: =COUNT('6 · Company data'!$O$750:$O$755)
A11: Technology | B11: =MEDIAN('6 · Company data'!$O$190:$O$202) | C11: =COUNT('6 · Company data'!$O$190:$O$202) | D11: =MEDIAN('6 · Company data'!$O$592:$O$674) | E11: =COUNT('6 · Company data'!$O$592:$O$674) | F11: =MEDIAN('6 · Company data'!$O$757:$O$761) | G11: =COUNT('6 · Company data'!$O$757:$O$761)
A12: Energy | B12: =MEDIAN('6 · Company data'!$O$96:$O$108) | C12: =COUNT('6 · Company data'!$O$96:$O$108) | D12: =MEDIAN('6 · Company data'!$O$339:$O$359) | E12: =COUNT('6 · Company data'!$O$339:$O$359) | F12: =MEDIAN('6 · Company data'!$O$728:$O$736) | G12: =COUNT('6 · Company data'!$O$728:$O$736)
A13: Basic Materials | B13: =MEDIAN('6 · Company data'!$O$6:$O$55) | C13: =COUNT('6 · Company data'!$O$6:$O$55) | D13: =MEDIAN('6 · Company data'!$O$208:$O$227) | E13: =COUNT('6 · Company data'!$O$208:$O$227) | F13: =MEDIAN('6 · Company data'!$O$706:$O$713) | G13: =COUNT('6 · Company data'!$O$706:$O$713) | H13: An eleven-point gap — wider than anything else in the table
A15: Australian miners fall roughly half as far again as American ones, and mining is a quarter of the ASX 200 — 50 companies out of 201. One sector with a much deeper cycle, dragging the whole index average behind it.

Sheet 5 · Banks vs miners
A1: Banks and miners, side by side
A2: The clearest view is inside Australia alone. Seven of each, so both medians are visible on the page and can be checked by eye.
A4: The seven banks
A5: Ticker | B5: Company | C5: Typical fall | D5: Worst since 2000 | E5: Note
A6: CBA.AX | B6: Commonwealth Bank of Australia | C6: ='6 · Company data'!$O$115 | D6: ='6 · Company data'!$P$115
A7: WBC.AX | B7: Westpac Banking Corporation | C7: ='6 · Company data'!$O$135 | D7: ='6 · Company data'!$P$135
A8: ANZ.AX | B8: ANZ Group Holdings Limited | C8: ='6 · Company data'!$O$110 | D8: ='6 · Company data'!$P$110
A9: NAB.AX | B9: National Australia Bank Limited | C9: ='6 · Company data'!$O$127 | D9: ='6 · Company data'!$P$127
A10: BEN.AX | B10: Bendigo and Adelaide Bank Limited | C10: ='6 · Company data'!$O$113 | D10: ='6 · Company data'!$P$113
A11: BOQ.AX | B11: Bank of Queensland Limited | C11: ='6 · Company data'!$O$114 | D11: ='6 · Company data'!$P$114
A12: MQG.AX | B12: Macquarie Group Limited | C12: ='6 · Company data'!$O$126 | D12: ='6 · Company data'!$P$126
B13: Median (the middle company) | C13: =MEDIAN(C6:C12) | E13: Middle of the seven values directly above
A16: The seven miners
A17: Ticker | B17: Company | C17: Typical fall | D17: Worst since 2000 | E17: Note
A18: BHP.AX | B18: BHP Group Limited | C18: ='6 · Company data'!$O$9 | D18: ='6 · Company data'!$P$9
A19: RIO.AX | B19: Rio Tinto Group | C19: ='6 · Company data'!$O$45 | D19: ='6 · Company data'!$P$45
A20: S32.AX | B20: South32 Limited | C20: ='6 · Company data'!$O$49 | D20: ='6 · Company data'!$P$49
A21: MIN.AX | B21: Mineral Resources Limited | C21: ='6 · Company data'!$O$34 | D21: ='6 · Company data'!$P$34
A22: NST.AX | B22: Northern Star Resources Limited | C22: ='6 · Company data'!$O$37 | D22: ='6 · Company data'!$P$37
A23: FMG.AX | B23: Fortescue Ltd | C23: ='6 · Company data'!$O$23 | D23: ='6 · Company data'!$P$23
A24: IGO.AX | B24: IGO Limited | C24: ='6 · Company data'!$O$26 | D24: ='6 · Company data'!$P$26
B25: Median (the middle company) | C25: =MEDIAN(C18:C24) | E25: Middle of the seven values directly above
B27: A typical mining fall is this many times a typical banking one | C27: =C25/C13
A29: The wrinkle: BHP and Rio Tinto sit with the BANKS, not with the miners — both around −17%. The two giant diversified miners have been far steadier than the pure-play producers beneath them. "Mining is volatile" is true of the sector, and not especially true of its two largest members.

Sheet 6 · Company data
A1: Every company measured
A2: Sorted by index, then sector, then ticker — so each block used on sheets 2–5 is a single unbroken range of rows. Companies below the index members are covered by MajorCycle but are not in any of the three indices; they are excluded from every published figure.
A4: Ticker | B4: Company | C4: Market | D4: Index | E4: Sector | F4: Market cap (own currency) | G4: Market cap source | H4: Rank in index | I4: In largest 60? | J4: First price we hold | K4: Trading days used | L4: Window start | M4: Window end | N4: Falls counted | O4: Typical fall | P4: Worst fall since 2000 | Q4: Typical rebound | R4: Now vs 1-yr high | S4: Largest-60 typical fall (helper)
A5: SGH.AX | B5: SGH Limited | C5: AU | D5: ASX 200 | E5: (not classified) | F5: 16133407744 | G5: nightly refresh | H5: 43 | I5: Yes | J5: 1993-08-31 | K5: 6780 | L5: 2000-01-03 | M5: 2026-08-26 | N5: 341 | O5: -20.4563 | P5: -64.782 | Q5: 48.0851 | R5: -22.504 | S5: =IF($I5="Yes",$O5,"")
A6: AAI.AX | B6: Alcoa Corporation | C6: AU | D6: ASX 200 | E6: Basic Materials | F6: 18180720640 | G6: nightly refresh | H6: 39 | I6: Yes | J6: 2024-07-24 | K6: 531 | L6: 2024-07-24 | M6: 2026-08-26 | N6: 28 | O6: -27.2729 | P6: -50.1311 | Q6: 71.4067 | R6: -39.8914 | S6: =IF($I6="Yes",$O6,"")
A7: ALK.AX | B7: Alkane Resources Ltd | C7: AU | D7: ASX 200 | E7: Basic Materials | F7: 2664099328 | G7: nightly refresh | H7: 144 | I7: No | J7: 1988-01-29 | K7: 6780 | L7: 2000-01-03 | M7: 2026-08-26 | N7: 302 | O7: -38.6353 | P7: -77.3109 | Q7: 113.6312 | R7: -0.5025 | S7: =IF($I7="Yes",$O7,"")
A8: BGL.AX | B8: Bellevue Gold Limited | C8: AU | D8: ASX 200 | E8: Basic Materials | F8: 2490808832 | G8: nightly refresh | H8: 149 | I8: No | J8: 2005-12-19 | K8: 5231 | L8: 2005-12-19 | M8: 2026-08-26 | N8: 169 | O8: -42.1879 | P8: -94.7297 | Q8: 195.5076 | R8: -13.75 | S8: =IF($I8="Yes",$O8,"")
A9: BHP.AX | B9: BHP Group Limited | C9: AU | D9: ASX 200 | E9: Basic Materials | F9: 337508139008 | G9: nightly refresh | H9: 1 | I9: Yes | J9: 1988-01-29 | K9: 6780 | L9: 2000-01-03 | M9: 2026-08-26 | N9: 343 | O9: -16.9052 | P9: -57.2175 | Q9: 41.0717 | R9: -1.9921 | S9: =IF($I9="Yes",$O9,"")
A10: BSL.AX | B10: BlueScope Steel Limited | C10: AU | D10: ASX 200 | E10: Basic Materials | F10: 13431454720 | G10: nightly refresh | H10: 47 | I10: Yes | J10: 2002-07-12 | K10: 6121 | L10: 2002-07-12 | M10: 2026-08-26 | N10: 327 | O10: -23.5839 | P10: -81.6446 | Q10: 63.2307 | R10: -12.7623 | S10: =IF($I10="Yes",$O10,"")
A11: CIA.AX | B11: Champion Iron Limited | C11: AU | D11: ASX 200 | E11: Basic Materials | F11: 1976965632 | G11: nightly refresh | H11: 162 | I11: No | J11: 2007-06-05 | K11: 4865 | L11: 2007-06-05 | M11: 2026-08-26 | N11: 191 | O11: -30.8815 | P11: -87.8035 | Q11: 128.607 | R11: -46.0212 | S11: =IF($I11="Yes",$O11,"")
A12: CMM.AX | B12: Capricorn Metals Ltd | C12: AU | D12: ASX 200 | E12: Basic Materials | F12: 7927041024 | G12: nightly refresh | H12: 77 | I12: No | J12: 2008-07-07 | K12: 4590 | L12: 2008-07-07 | M12: 2026-08-26 | N12: 165 | O12: -31.4284 | P12: -90 | Q12: 181.9441 | R12: -2.6287 | S12: =IF($I12="Yes",$O12,"")
A13: CSC.AX | B13: Capstone Copper Corp. | C13: AU | D13: ASX 200 | E13: Basic Materials | F13: 12421816320 | G13: nightly refresh | H13: 51 | I13: Yes | J13: 2024-04-08 | K13: 606 | L13: 2024-04-08 | M13: 2026-08-26 | N13: 39 | O13: -25.1895 | P13: -50.64 | Q13: 72.7076 | R13: -7.4033 | S13: =IF($I13="Yes",$O13,"")
A14: CYL.AX | B14: Catalyst Metals Limited | C14: AU | D14: ASX 200 | E14: Basic Materials | F14: 1769219200 | G14: nightly refresh | H14: 172 | I14: No | J14: 2006-07-26 | K14: 5082 | L14: 2006-07-26 | M14: 2026-08-26 | N14: 164 | O14: -31.7063 | P14: -78.3784 | Q14: 143.9548 | R14: -29.4898 | S14: =IF($I14="Yes",$O14,"")
A15: DNL.AX | B15: Dyno Nobel Limited | C15: AU | D15: ASX 200 | E15: Basic Materials | F15: 6603401728 | G15: nightly refresh | H15: 86 | I15: No | J15: 2003-07-25 | K15: 5851 | L15: 2003-07-25 | M15: 2026-08-26 | N15: 286 | O15: -21.5925 | P15: -79.3422 | Q15: 56.9261 | R15: -5.7357 | S15: =IF($I15="Yes",$O15,"")
A16: DRR.AX | B16: Deterra Royalties Limited | C16: AU | D16: ASX 200 | E16: Basic Materials | F16: 2186860288 | G16: nightly refresh | H16: 158 | I16: No | J16: 2020-10-23 | K16: 1477 | L16: 2020-10-23 | M16: 2026-08-26 | N16: 72 | O16: -16.2694 | P16: -35.3175 | Q16: 26.1147 | R16: -11.7155 | S16: =IF($I16="Yes",$O16,"")
... A765: H.TO | B765: Hydro One Limited | C765: CA | D765: S&P/TSX 60 | E765: Utilities | F765: 32135147520 | G765: nightly refresh | H765: 44 | I765: Yes | J765: 2015-11-17 | K765: 2703 | L765: 2015-11-17 | M765: 2026-08-25 | N765: 88 | O765: -9.953 | P765: -28.243 | Q765: 25.465 | R765: -11.722 | S765: =IF($I765="Yes",$O765,"")
A766: ^AXJO | B766: ^AXJO | C766: INDEX | D766: — not an index member — | E766: (not classified) | G766: nightly refresh | I766: — | J766: 1992-11-23 | K766: 6734 | L766: 2000-01-04 | M766: 2026-08-26 | N766: 220 | O766: -13.3708 | P766: -49.8399 | Q766: 19.172 | R766: -1.8168 | S766: =IF($I766="Yes",$O766,"")
A767: ^GSPC | B767: ^GSPC | C767: INDEX | D767: — not an index member — | E767: (not classified) | G767: nightly refresh | I767: — | J767: 1927-12-30 | K767: 6701 | L767: 2000-01-03 | M767: 2026-08-25 | N767: 198 | O767: -15.8968 | P767: -53.0266 | Q767: 24.5729 | R767: -1.7836 | S767: =IF($I767="Yes",$O767,"")
A768: ^GSPTSE | B768: ^GSPTSE | C768: INDEX | D768: — not an index member — | E768: (not classified) | G768: nightly refresh | I768: — | J768: 1979-06-29 | K768: 6693 | L768: 2000-01-04 | M768: 2026-08-25 | N768: 206 | O768: -15.4583 | P768: -50.0693 | Q768: 22.1531 | R768: -0.092 | S768: =IF($I768="Yes",$O768,"")
A769: ^IXIC | B769: ^IXIC | C769: INDEX | D769: — not an index member — | E769: (not classified) | G769: nightly refresh | I769: — | J769: 1971-02-05 | K769: 6701 | L769: 2000-01-03 | M769: 2026-08-25 | N769: 245 | O769: -18.8965 | P769: -63.9638 | Q769: 32.3131 | R769: -3.8209 | S769: =IF($I769="Yes",$O769,"")
A770: 29M.AX | B770: 29Metals Limited | C770: AU | D770: — not an index member — | E770: Basic Materials | F770: 595026048 | G770: nightly refresh | I770: — | J770: 2021-07-02 | K770: 1304 | L770: 2021-07-02 | M770: 2026-08-26 | N770: 57 | O770: -49.4943 | P770: -90.0658 | Q770: 111.6825 | R770: -46.6667 | S770: =IF($I770="Yes",$O770,"")
A771: AGI.TO | B771: Alamos Gold Inc. | C771: CA | D771: — not an index member — | E771: Basic Materials | F771: 21817665536 | G771: nightly refresh | I771: — | J771: 2003-10-09 | K771: 5744 | L771: 2003-10-09 | M771: 2026-08-25 | N771: 356 | O771: -26.241 | P771: -66.8109 | Q771: 77.1805 | R771: -28.676 | S771: =IF($I771="Yes",$O771,"")
A772: AIS.AX | B772: Aeris Resources Limited | C772: AU | D772: — not an index member — | E772: Basic Materials | F772: 793454912 | G772: nightly refresh | I772: — | J772: 2011-02-11 | K772: 3930 | L772: 2011-02-11 | M772: 2026-08-26 | N772: 142 | O772: -49.5153 | P772: -97.8017 | Q772: 133.4334 | R772: -32.1429 | S772: =IF($I772="Yes",$O772,"")
A773: CE | B773: Celanese Corporation | C773: US | D773: — not an index member — | E773: Basic Materials | F773: 4905777152 | G773: nightly refresh | I773: — | J773: 2005-01-21 | K773: 5432 | L773: 2005-01-21 | M773: 2026-08-25 | N773: 286 | O773: -23.7699 | P773: -85.1627 | Q773: 62.1725 | R773: -37.0297 | S773: =IF($I773="Yes",$O773,"")
A774: EMN | B774: Eastman Chemical Company | C774: US | D774: — not an index member — | E774: Basic Materials | F774: 8337840640 | G774: nightly refresh | I774: — | J774: 1993-12-14 | K774: 6701 | L774: 2000-01-03 | M774: 2026-08-25 | N774: 348 | O774: -19.5013 | P774: -76.3491 | Q774: 50.9102 | R774: -12.6784 | S774: =IF($I774="Yes",$O774,"")
A775: FMC | B775: FMC Corporation | C775: US | D775: — not an index member — | E775: Basic Materials | F775: 1387513344 | G775: nightly refresh | I775: — | J775: 1980-03-17 | K775: 6701 | L775: 2000-01-03 | M775: 2026-08-25 | N775: 343 | O775: -23.8075 | P775: -79.266 | Q775: 48.5877 | R775: -71.763 | S775: =IF($I775="Yes",$O775,"")
A776: NUF.AX | B776: Nufarm Limited | C776: AU | D776: — not an index member — | E776: Basic Materials | F776: 1210411392 | G776: nightly refresh | I776: — | J776: 1988-11-30 | K776: 6780 | L776: 2000-01-03 | M776: 2026-08-26 | N776: 339 | O776: -24.7708 | P776: -73.3392 | Q776: 42.4954 | R776: -3.7383 | S776: =IF($I776="Yes",$O776,"")
A777: WFG.TO | B777: West Fraser Timber Co. Ltd. | C777: CA | D777: — not an index member — | E777: Basic Materials | F777: 7369172992 | G777: nightly refresh | I777: — | J777: 1986-05-07 | K777: 6695 | L777: 2000-01-04 | M777: 2026-08-25 | N777: 376 | O777: -20.865 | P777: -67.2536 | Q777: 47.9931 | R777: -8.8782 | S777: =IF($I777="Yes",$O777,"")
A778: AIM.AX | B778: Ai-Media Technologies Limited | C778: AU | D778: — not an index member — | E778: Communication Services | F778: 54856608 | G778: nightly refresh | I778: — | J778: 2020-09-15 | K778: 1505 | L778: 2020-09-15 | M778: 2026-08-26 | N778: 62 | O778: -40.8562 | P778: -79.4737 | Q778: 74.1558 | R778: -78.4211 | S778: =IF($I778="Yes",$O778,"")
A779: EA | B779: Electronic Arts Inc | C779: US | D779: — not an index member — | E779: Communication Services | F779: 52925640704 | G779: nightly refresh | I779: — | J779: 1989-09-20 | K779: 6690 | L779: 2000-01-03 | M779: 2026-08-10 | N779: 376 | O779: -21.1203 | P779: -74.3207 | Q779: 49.1327 | R779: -0.2379 | S779: =IF($I779="Yes",$O779,"")
A780: MTCH | B780: Match Group, Inc. | C780: US | D780: — not an index member — | E780: Communication Services | F780: 9813522432 | G780: nightly refresh | I780: — | J780: 1993-01-19 | K780: 6701 | L780: 2000-01-03 | M780: 2026-08-25 | N780: 384 | O780: -24.8206 | P780: -77.2198 | Q780: 57.4744 | R780: -0.7179 | S780: =IF($I780="Yes",$O780,"")
A781: QBR-B.TO | B781: Quebecor Inc. | C781: CA | D781: — not an index member — | E781: Communication Services | F781: 14052877312 | G781: nightly refresh | I781: — | J781: 1995-01-12 | K781: 6693 | L781: 2000-01-04 | M781: 2026-08-25 | N781: 325 | O781: -18.4043 | P781: -63.9487 | Q781: 38.424 | R781: -11.9859 | S781: =IF($I781="Yes",$O781,"")
... A795: GYG.AX | B795: Guzman y Gomez Limited | C795: AU | D795: — not an index member — | E795: Consumer Cyclical | F795: 2928751616 | G795: nightly refresh | I795: — | J795: 2024-06-20 | K795: 555 | L795: 2024-06-20 | M795: 2026-08-26 | N795: 39 | O795: -32.9675 | P795: -58.217 | Q795: 40.9842 | R795: -14.4606 | S795: =IF($I795="Yes",$O795,"")
A796: KMX | B796: CarMax, Inc. | C796: US | D796: — not an index member — | E796: Consumer Cyclical | G796: nightly refresh | I796: — | J796: 1997-02-04 | K796: 6701 | L796: 2000-01-03 | M796: 2026-08-25 | N796: 372 | O796: -25.0213 | P796: -73.9548 | Q796: 81.712 | R796: -0.5728 | S796: =IF($I796="Yes",$O796,"")
A797: LKQ | B797: LKQ Corporation | C797: US | D797: — not an index member — | E797: Consumer Cyclical | F797: 6514803712 | G797: nightly refresh | I797: — | J797: 2003-10-06 | K797: 5758 | L797: 2003-10-06 | M797: 2026-08-25 | N797: 337 | O797: -18.486 | P797: -64.48 | Q797: 52.756 | R797: -30.1939 | S797: =IF($I797="Yes",$O797,"")
A798: MHK | B798: Mohawk Industries, Inc. | C798: US | D798: — not an index member — | E798: Consumer Cyclical | F798: 8952950784 | G798: nightly refresh | I798: — | J798: 1992-04-01 | K798: 6701 | L798: 2000-01-03 | M798: 2026-08-25 | N798: 369 | O798: -23.0167 | P798: -78.6897 | Q798: 55.0584 | R798: -6.5395 | S798: =IF($I798="Yes",$O798,"")
A799: SIG | B799: Signet Jewelers Limited | C799: US | D799: — not an index member — | E799: Consumer Cyclical | G799: nightly refresh | I799: — | J799: 1988-07-14 | K799: 6701 | L799: 2000-01-03 | M799: 2026-08-25 | N799: 376 | O799: -27.7068 | P799: -83.3798 | Q799: 84.5729 | R799: -22.9308 | S799: =IF($I799="Yes",$O799,"")
A800: SKC.AX | B800: SkyCity Entertainment Group Limited | C800: AU | D800: — not an index member — | E800: Consumer Cyclical | F800: 617710848 | G800: nightly refresh | I800: — | J800: 1999-05-07 | K800: 6780 | L800: 2000-01-03 | M800: 2026-08-26 | N800: 295 | O800: -20.1426 | P800: -68.308 | Q800: 32.5918 | R800: -32.7536 | S800: =IF($I800="Yes",$O800,"")
A801: TPW.AX | B801: Temple & Webster Group Ltd | C801: AU | D801: — not an index member — | E801: Consumer Cyclical | F801: 538445888 | G801: nightly refresh | I801: — | J801: 2015-12-10 | K801: 2710 | L801: 2015-12-10 | M801: 2026-08-26 | N801: 132 | O801: -35.0098 | P801: -87.6289 | Q801: 157.9481 | R801: -81.1792 | S801: =IF($I801="Yes",$O801,"")
A802: UNI.AX | B802: Universal Store Holdings Limited | C802: AU | D802: — not an index member — | E802: Consumer Cyclical | F802: 638317120 | G802: nightly refresh | I802: — | J802: 2020-11-17 | K802: 1460 | L802: 2020-11-17 | M802: 2026-08-26 | N802: 73 | O802: -23.8471 | P802: -59.903 | Q802: 71.5635 | R802: -15.3061 | S802: =IF($I802="Yes",$O802,"")
...

Sheet 7 · Outside claims
A1: The claims that are NOT ours
A2: Four figures in the article come from a Morgan Stanley study, not from our data. Each was read in the source document itself and is quoted here word for word.
A4: Michael J. Mauboussin & Dan Callahan, "Drawdowns and Recoveries: Base Rates for Bottoms and Bounces", Counterpoint Global Insights, Morgan Stanley — 21 May 2025
A5: https://www.morganstanley.com/im/en-us/individual-investor/insights/consilient-observer/drawdowns-and-recoveries.html
A7: The article says | B7: The paper says, word for word | C7: Checked
A8: more than 6,500 US companies, 1985–2024 | B8: "more than 6,500 companies from 1985 to 2024" | C8: Yes
A9: the typical company's worst fall runs to 85% | B9: "The median drawdown was 85 percent" | C9: Yes
A10: more than half never get back to their old high | B10: "about 54 percent of stocks never return to par after hitting bottom" | C10: Yes
A11: America's six greatest wealth creators averaged a worst fall of 80.3% | B11: "The average maximum drawdown for the stocks of the top 6 companies was 80.3 percent, similar to the average of the full sample" | C11: Yes
A13: Two things about that study worth knowing
A14: Its sample EXCLUDES companies that went bankrupt or delisted (which would show 100% falls), and anything that never reached a $1m market cap. So it is less failure-biased than it first appears.
A16: It measures ONE worst-ever fall per company, from an all-time peak. Our figures measure the AVERAGE ordinary fall from a one-year high. They answer different questions, and the article says so rather than inviting a false comparison.

Sheet 8 · Spot checks
A1: Five figures you can confirm yourself, on public websites
A2: Nobody can verify 761 companies by hand. These five are enough to show the method is sound: if they are right, the rest follow from the same code.
A4: # | B4: What to check | C4: Our figure | D4: Where to check it
A5: 1 | B5: Commonwealth Bank's typical fall | C5: ='6 · Company data'!$O$115 | D5: https://www.marketindex.com.au/asx/cba
A6: 2 | B6: Fortescue's worst fall since 2000 | C6: ='6 · Company data'!$P$23 | D6: https://www.marketindex.com.au/asx/fmg
A7: 3 | B7: Westpac's worst fall came in March 2020, not the GFC | C7: March 2020 | D7: https://www.marketindex.com.au/asx/wbc
A8: 4 | B8: Mining is 50 of the 201 ASX 200 companies | C8: 50 | D8: https://www.spglobal.com/spdji/en/indices/equity/sp-asx-200/
A9: 5 | B9: Apple's worst fall since 2000 | C9: ='6 · Company data'!$P$592 | D9: Any long-run Apple price chart
